Sat May 30 14:01:56 COT 2020 : Servidor de red Apache Derby: Se ha iniciado 10.14.2.0 - (1828579) y está listo para aceptar las conexiones en el puerto 1527
----------------------------------------------------------------
Sat May 30 14:10:04 COT 2020:
 Iniciando instancia a816c00e-0172-66f6-49ea-00005e0e7d4f de Derby, versión The Apache Software Foundation - Apache Derby - 10.14.2.0 - (1828579): 
en el directorio de base de datos C:\Users\Hp\Documents\NetBeansProjects\EasyCoffee\db\EASYCOFFEBD con el cargador de clases sun.misc.Launcher$AppClassLoader@1d44bcfa
Cargado desde file:/C:/Users/Hp/Documents/NetBeansProjects/db-derby-10.14.2.0-bin/lib/derby.jar
java.vendor=Oracle Corporation
java.runtime.version=1.8.0_191-b12
user.dir=C:\Users\Hp\Documents\NetBeansProjects\db-derby-10.14.2.0-bin
os.name=Windows 10
os.arch=amd64
os.version=10.0
derby.system.home=C:\Users\Hp\Documents\NetBeansProjects\EasyCoffee\db
Cargador de clases de base de datos iniciado - derby.database.classpath=''
Sat May 30 14:10:04 COT 2020 Thread[DRDAConnThread_2,5,main] (XID = 535), (SESSIONID = 0), (DATABASE = easycoffebd), (DRDAID = {1}), Cleanup action starting
java.sql.SQLNonTransientConnectionException: Se ha producido un fallo de autenticación de conexión. Motivo: Autenticación no válida..
	at org.apache.derby.impl.jdbc.SQLExceptionFactory.getSQLException(Unknown Source)
	at org.apache.derby.impl.jdbc.SQLExceptionFactory.getSQLException(Unknown Source)
	at org.apache.derby.impl.jdbc.Util.generateCsSQLException(Unknown Source)
	at org.apache.derby.impl.jdbc.Util.generateCsSQLException(Unknown Source)
	at org.apache.derby.impl.jdbc.EmbedConnection.newSQLException(Unknown Source)
	at org.apache.derby.impl.jdbc.EmbedConnection.checkUserCredentials(Unknown Source)
	at org.apache.derby.impl.jdbc.EmbedConnection.<init>(Unknown Source)
	at org.apache.derby.jdbc.InternalDriver$1.run(Unknown Source)
	at org.apache.derby.jdbc.InternalDriver$1.run(Unknown Source)
	at java.security.AccessController.doPrivileged(Native Method)
	at org.apache.derby.jdbc.InternalDriver.getNewEmbedConnection(Unknown Source)
	at org.apache.derby.jdbc.InternalDriver.connect(Unknown Source)
	at org.apache.derby.jdbc.InternalDriver.connect(Unknown Source)
	at org.apache.derby.jdbc.EmbeddedDriver.connect(Unknown Source)
	at org.apache.derby.impl.drda.Database.makeConnection(Unknown Source)
	at org.apache.derby.impl.drda.DRDAConnThread.getConnFromDatabaseName(Unknown Source)
	at org.apache.derby.impl.drda.DRDAConnThread.verifyUserIdPassword(Unknown Source)
	at org.apache.derby.impl.drda.DRDAConnThread.parseSECCHK(Unknown Source)
	at org.apache.derby.impl.drda.DRDAConnThread.parseDRDAConnection(Unknown Source)
	at org.apache.derby.impl.drda.DRDAConnThread.processCommands(Unknown Source)
	at org.apache.derby.impl.drda.DRDAConnThread.run(Unknown Source)
Caused by: ERROR 08004: Se ha producido un fallo de autenticación de conexión. Motivo: Autenticación no válida..
	at org.apache.derby.iapi.error.StandardException.newException(Unknown Source)
	at org.apache.derby.impl.jdbc.SQLExceptionFactory.wrapArgsForTransportAcrossDRDA(Unknown Source)
	... 21 more
============= begin nested exception, level (1) ===========
ERROR 08004: Se ha producido un fallo de autenticación de conexión. Motivo: Autenticación no válida..
	at org.apache.derby.iapi.error.StandardException.newException(Unknown Source)
	at org.apache.derby.impl.jdbc.SQLExceptionFactory.wrapArgsForTransportAcrossDRDA(Unknown Source)
	at org.apache.derby.impl.jdbc.SQLExceptionFactory.getSQLException(Unknown Source)
	at org.apache.derby.impl.jdbc.SQLExceptionFactory.getSQLException(Unknown Source)
	at org.apache.derby.impl.jdbc.Util.generateCsSQLException(Unknown Source)
	at org.apache.derby.impl.jdbc.Util.generateCsSQLException(Unknown Source)
	at org.apache.derby.impl.jdbc.EmbedConnection.newSQLException(Unknown Source)
	at org.apache.derby.impl.jdbc.EmbedConnection.checkUserCredentials(Unknown Source)
	at org.apache.derby.impl.jdbc.EmbedConnection.<init>(Unknown Source)
	at org.apache.derby.jdbc.InternalDriver$1.run(Unknown Source)
	at org.apache.derby.jdbc.InternalDriver$1.run(Unknown Source)
	at java.security.AccessController.doPrivileged(Native Method)
	at org.apache.derby.jdbc.InternalDriver.getNewEmbedConnection(Unknown Source)
	at org.apache.derby.jdbc.InternalDriver.connect(Unknown Source)
	at org.apache.derby.jdbc.InternalDriver.connect(Unknown Source)
	at org.apache.derby.jdbc.EmbeddedDriver.connect(Unknown Source)
	at org.apache.derby.impl.drda.Database.makeConnection(Unknown Source)
	at org.apache.derby.impl.drda.DRDAConnThread.getConnFromDatabaseName(Unknown Source)
	at org.apache.derby.impl.drda.DRDAConnThread.verifyUserIdPassword(Unknown Source)
	at org.apache.derby.impl.drda.DRDAConnThread.parseSECCHK(Unknown Source)
	at org.apache.derby.impl.drda.DRDAConnThread.parseDRDAConnection(Unknown Source)
	at org.apache.derby.impl.drda.DRDAConnThread.processCommands(Unknown Source)
	at org.apache.derby.impl.drda.DRDAConnThread.run(Unknown Source)
============= end nested exception, level (1) ===========
Cleanup action completed
Sat May 30 14:10:04 COT 2020 Thread[DRDAConnThread_2,5,main] (DATABASE = easycoffebd), (DRDAID = {1}), Se ha producido un fallo de autenticación de conexión. Motivo: Autenticación no válida..
